Workbook

Sheet Custom basket
A1: Instructions: | C1: Copy/paste the list below for the Single Geocode Market Baskets | E1: Copy/paste the list below for the Double Geocode Market Baskets
A2: - Perform steps 1-3 under the tab 'geocodes & mnemonic list'
A3: - Take the compiled basket of mnemonics on the right (copy all, do not worry about the blank space when pasting into the basket, it will automatically remove gaps)
C4: {=_xlfn.TOCOL('Single Geocode compiler'!$D$4:$BA$54,3)} -> FHHOLDQ.IUSA_MDEN | E4: {=_xlfn.TOCOL('Double Geocode Compiler'!$E$5:$BB$32,3)} -> FHHOLDQ.IUSA_DMSEB+FHHOLDQ.IUSA_DMEVE
C5: FPOP2024Q.IUSA_MDEN | E5: FPOP2024Q.IUSA_DMSEB+FPOP2024Q.IUSA_DMEVE
C6: FPOP2529Q.IUSA_MDEN | E6: FPOP2529Q.IUSA_DMSEB+FPOP2529Q.IUSA_DMEVE
A7: - Provide the name of the basket (e.g. TM Forecast - Data Buffet) and adjust | C7: FPOP3034Q.IUSA_MDEN | E7: FPOP3034Q.IUSA_DMSEB+FPOP3034Q.IUSA_DMEVE
A8: inside the script. It's recommended to keep a consistent name of the basket | C8: FPOPQ.IUSA_MDEN | E8: FPOPQ.IUSA_DMSEB+FPOPQ.IUSA_DMEVE
A9: for the MA DataBuffet API to pull this data. | C9: FYHHMEDQ.IUSA_MDEN | E9: (FPOPQ.IUSA_DMSEB*FYHHMEDQ.IUSA_DMSEB + FPOPQ.IUSA_DMEVE*FYHHMEDQ.IUSA_DMEVE) / (FPOPQ.IUSA_DMSEB + FPOPQ.IUSA_DMEVE)
C10: FET.IUSA_MDEN | E10: FET.IUSA_DMSEB+FET.IUSA_DMEVE
C11: FCPIU.IUSA_MDEN | E11: (FPOPQ.IUSA_DMSEB*FCPIU.IUSA_DMSEB + FPOPQ.IUSA_DMEVE*FCPIU.IUSA_DMEVE) / (FPOPQ.IUSA_DMSEB + FPOPQ.IUSA_DMEVE)
C12: FGDP$Q.IUSA_MDEN | E12: FGDP$Q.IUSA_DMSEB+FGDP$Q.IUSA_DMEVE
C13: FHPNR.IUSA_MDEN | E13: FHPNR.IUSA_DMSEB+FHPNR.IUSA_DMEVE
C14: FHPNM.IUSA_MDEN | E14: FHPNM.IUSA_DMSEB+FHPNM.IUSA_DMEVE
C15: FHX1.IUSA_MDEN | E15: FHX1.IUSA_DMSEB+FHX1.IUSA_DMEVE
C16: FHX1MED.IUSA_MDEN | E16: (FPOPQ.IUSA_DMSEB*FHX1MED.IUSA_DMSEB + FPOPQ.IUSA_DMEVE*FHX1MED.IUSA_DMEVE) / (FPOPQ.IUSA_DMSEB + FPOPQ.IUSA_DMEVE)
E17: FHHOLDQ.IUSA_DMSRF+FHHOLDQ.IUSA_DMSAF
E18: FPOP2024Q.IUSA_DMSRF+FPOP2024Q.IUSA_DMSAF
E19: FPOP2529Q.IUSA_DMSRF+FPOP2529Q.IUSA_DMSAF
E20: FPOP3034Q.IUSA_DMSRF+FPOP3034Q.IUSA_DMSAF
E21: FPOPQ.IUSA_DMSRF+FPOPQ.IUSA_DMSAF
E22: (FPOPQ.IUSA_DMSRF*FYHHMEDQ.IUSA_DMSRF + FPOPQ.IUSA_DMSAF*FYHHMEDQ.IUSA_DMSAF) / (FPOPQ.IUSA_DMSRF + FPOPQ.IUSA_DMSAF)
E23: FET.IUSA_DMSRF+FET.IUSA_DMSAF
E24: (FPOPQ.IUSA_DMSRF*FCPIU.IUSA_DMSRF + FPOPQ.IUSA_DMSAF*FCPIU.IUSA_DMSAF) / (FPOPQ.IUSA_DMSRF + FPOPQ.IUSA_DMSAF)
E25: FGDP$Q.IUSA_DMSRF+FGDP$Q.IUSA_DMSAF
E26: FHPNR.IUSA_DMSRF+FHPNR.IUSA_DMSAF
E27: FHPNM.IUSA_DMSRF+FHPNM.IUSA_DMSAF
E28: FHX1.IUSA_DMSRF+FHX1.IUSA_DMSAF
... E42: (FPOPQ.IUSA_MDUR*FHX1MED.IUSA_MDUR + FPOPQ.IUSA_MRAL*FHX1MED.IUSA_MRAL) / (FPOPQ.IUSA_MDUR + FPOPQ.IUSA_MRAL)
C54: FHHOLDQ.IUSA_DMLOS
C55: FPOP2024Q.IUSA_DMLOS
C56: FPOP2529Q.IUSA_DMLOS
C57: FPOP3034Q.IUSA_DMLOS
C58: FPOPQ.IUSA_DMLOS
C59: FYHHMEDQ.IUSA_DMLOS
C60: FET.IUSA_DMLOS
C61: FCPIU.IUSA_DMLOS
C62: FGDP$Q.IUSA_DMLOS
C63: FHPNR.IUSA_DMLOS
C64: FHPNM.IUSA_DMLOS
...

Sheet geocodes & mnemonic list
B1: 1. Add market to the list below. Use REIS defined market naming and abbreviations | I1: 3. Add mnemonics
B2: (Note: For markets with two mnemonics, a separate process will aggregate the data
B3: append a '1' and '2' to the market name as shown below for SF, SEA and RAL-DUR)
B5: Market | C5: MMC_abbrev | D5: Market_abbrev | E5: Geocode | I5: Number | J5: Mnemonics | K5: Description | L5: Method
A6: 1 | B6: Denver | C6: DEN | D6: DE | E6: IUSA_MDEN | I6: 1 | J6: FHHOLDQ | K6: Baseline Scenario (August 2025): Households: Total, (Ths. #, NSA) | L6: sum
A7: =A6+1 -> 2 | B7: Los Angeles | C7: LA | D7: LA | E7: IUSA_DMLOS | I7: =I6+1 -> 2 | J7: FPOP2024Q | K7: Baseline Scenario (August 2025): Population: Ages 20-24, (Ths. #, NSA) | L7: sum
A8: =A7+1 -> 3 | B8: Oakland-East Bay | C8: OAK | D8: OA | E8: IUSA_DMOAK | I8: =I7+1 -> 3 | J8: FPOP2529Q | K8: Baseline Scenario (August 2025): Population: Ages 25-29, (Ths. #, NSA) | L8: sum
A9: =A8+1 -> 4 | B9: Orange County | C9: OC | D9: OC | E9: IUSA_DMANA | I9: =I8+1 -> 4 | J9: FPOP3034Q | K9: Baseline Scenario (August 2025): Population: Ages 30-34, (Ths. #, NSA) | L9: sum
A10: =A9+1 -> 5 | B10: Portland | C10: POR | D10: PO | E10: IUSA_MPOT | I10: =I9+1 -> 5 | J10: FPOPQ | K10: Baseline Scenario (August 2025): Population: Total, (Ths. #, NSA) | L10: sum
A11: =A10+1 -> 6 | B11: San Jose | C11: SJ | D11: SJ | E11: IUSA_MSAJ | I11: =I10+1 -> 6 | J11: FYHHMEDQ | K11: Baseline Scenario (August 2025): Income: Median Household, (USD, SAAR) | L11: weighted avg
A12: =A11+1 -> 7 | B12: San Diego | C12: SD | D12: SD | E12: IUSA_MSAN | I12: =I11+1 -> 7 | J12: FET | K12: Baseline Scenario (August 2025): Employment: Total Non-Agricultural, (Ths. #, SA) | L12: sum
A13: =A12+1 -> 8 | B13: Ventura County | C13: VC | D13: VN | E13: IUSA_MOXN | I13: =I12+1 -> 8 | J13: FCPIU | K13: Baseline Scenario (August 2025): CPI: Total - All Urban Consumers, (Index 1982-84=100, SA) | L13: weighted avg
A14: =A13+1 -> 9 | B14: Fairfield County | C14: FC | D14: FC | E14: IUSA_MBSD | I14: =I13+1 -> 9 | J14: FGDP$Q | K14: Baseline Scenario (August 2025): Gross Metro Product: Total, (Bil. Ch. 2017 USD, SAAR) | L14: sum
A15: =A14+1 -> 10 | B15: Boston | C15: BOS | D15: BO | E15: IUSA_MBOS | I15: =I14+1 -> 10 | J15: FHPNR | K15: Baseline Scenario (August 2025): Permits: Residential - Total, (#, SAAR) | L15: sum
A16: =A15+1 -> 11 | B16: New York Metro | C16: NYM | D16: NY | E16: IUSA_DMNWY | I16: =I15+1 -> 11 | J16: FHPNM | K16: Baseline Scenario (August 2025): Permits: Residential - Multifamily, (#, SAAR) | L16: sum
A17: =A16+1 -> 12 | B17: Northern New Jersey | C17: NNJ | D17: NJ | E17: IUSA_DMNEK | I17: =I16+1 -> 12 | J17: FHX1 | K17: Baseline Scenario (August 2025): Home Sales: Existing Single-Family, (Ths. #, SAAR) | L17: sum
A18: =A17+1 -> 13 | B18: Long Island | C18: LI | D18: LI | E18: IUSA_DMNAS | I18: =I17+1 -> 13 | J18: FHX1MED | K18: Baseline Scenario (August 2025): Existing Single-Family Home Price: Median, (Ths. USD, SA) | L18: weighted avg
A19: =A18+1 -> 14 | B19: District of Columbia | C19: DC | D19: DC | E19: IUSA_MWAA | I19: =I18+1 -> 14
A20: =A19+1 -> 15 | B20: Atlanta | C20: ATL | D20: AT | E20: IUSA_MATS | I20: =I19+1 -> 15
A21: =A20+1 -> 16 | B21: Austin | C21: AUS | D21: AU | E21: IUSA_MAUS | I21: =I20+1 -> 16
A22: =A21+1 -> 17 | B22: Central New Jersey | C22: CNJ | D22: CJ | E22: IUSA_DMLNB | I22: =I21+1 -> 17
A23: =A22+1 -> 18 | B23: Charleston | C23: CHS | D23: CN | E23: IUSA_MCHS | I23: =I22+1 -> 18
A24: =A23+1 -> 19 | B24: Charlotte | C24: CHR | D24: CR | E24: IUSA_MCLT | I24: =I23+1 -> 19
A25: =A24+1 -> 20 | B25: Dallas | C25: DAL | D25: DA | E25: IUSA_DMDAL | I25: =I24+1 -> 20
A26: =A25+1 -> 21 | B26: Fort Lauderdale | C26: FL | D26: FL | E26: IUSA_DMFOT | I26: =I25+1 -> 21
A27: =A26+1 -> 22 | B27: Fort Worth | C27: FW | D27: FW | E27: IUSA_DMDLL | I27: =I26+1 -> 22
A28: =A27+1 -> 23 | B28: Miami | C28: MIA | D28: MI | E28: IUSA_DMMIA | I28: =I27+1 -> 23
A29: =A28+1 -> 24 | B29: Orlando | C29: ORL | D29: OR | E29: IUSA_MORL | I29: =I28+1 -> 24
A30: =A29+1 -> 25 | B30: San Bernardino/Riverside | C30: SB | D30: SB | E30: IUSA_MRIV | I30: =I29+1 -> 25
... A38: =A37+1 -> 33 | B38: Raleigh-Durham 2 | C38: DUR | D38: RD | E38: IUSA_MDUR | I38: =I37+1 -> 33
A39: =A38+1 -> 34 | I39: =I38+1 -> 34
A40: =A39+1 -> 35 | I40: =I39+1 -> 35
A41: =A40+1 -> 36 | I41: =I40+1 -> 36
A42: =A41+1 -> 37 | I42: =I41+1 -> 37
A43: =A42+1 -> 38 | I43: =I42+1 -> 38
A44: =A43+1 -> 39 | I44: =I43+1 -> 39
A45: =A44+1 -> 40 | I45: =I44+1 -> 40
A46: =A45+1 -> 41 | I46: =I45+1 -> 41
A47: =A46+1 -> 42 | I47: =I46+1 -> 42
A48: =A47+1 -> 43 | I48: =I47+1 -> 43
...

Sheet Single Geocode compiler
D1: 1 | E1: 2 | F1: 3 | G1: 4 | H1: 5 | I1: 6 | J1: 7 | K1: 8 | L1: 9 | M1: 10 | N1: 11 | O1: 12 | P1: 13 | Q1: 14 | R1: 15 | S1: 16 | T1: 17 | U1: 18 | V1: 19 | W1: 20 | X1: 21 | Y1: 22 | Z1: 23 | AA1: 24 | AB1: 25 | AC1: 26 | AD1: 27 | AE1: 28 | AF1: 29 | AG1: 30 | AH1: 31 | AI1: 32 | AJ1: 33 | AK1: 34 | AL1: 35 | AM1: 36 | AN1: 37 | AO1: 38 | AP1: 39 | AQ1: 40 | AR1: 41 | AS1: 42 | AT1: 43 | AU1: 44 | AV1: 45 | AW1: 46 | AX1: 47 | AY1: 48 | AZ1: 49 | BA1: 50
C2: Mnemonics: | D2: =IF(VLOOKUP(D$1,'geocodes & mnemonic list'!$I:$J,2,FALSE)=0,"", VLOOKUP(D$1,'geocodes & mnemonic list'!$I:$J,2,FALSE)) -> FHHOLDQ | E2: =IF(VLOOKUP(E$1,'geocodes & mnemonic list'!$I:$J,2,FALSE)=0,"", VLOOKUP(E$1,'geocodes & mnemonic list'!$I:$J,2,FALSE)) -> FPOP2024Q | F2: =IF(VLOOKUP(F$1,'geocodes & mnemonic list'!$I:$J,2,FALSE)=0,"", VLOOKUP(F$1,'geocodes & mnemonic list'!$I:$J,2,FALSE)) -> FPOP2529Q | G2: =IF(VLOOKUP(G$1,'geocodes & mnemonic list'!$I:$J,2,FALSE)=0,"", VLOOKUP(G$1,'geocodes & mnemonic list'!$I:$J,2,FALSE)) -> FPOP3034Q | H2: =IF(VLOOKUP(H$1,'geocodes & mnemonic list'!$I:$J,2,FALSE)=0,"", VLOOKUP(H$1,'geocodes & mnemonic list'!$I:$J,2,FALSE)) -> FPOPQ | I2: =IF(VLOOKUP(I$1,'geocodes & mnemonic list'!$I:$J,2,FALSE)=0,"", VLOOKUP(I$1,'geocodes & mnemonic list'!$I:$J,2,FALSE)) -> FYHHMEDQ | J2: =IF(VLOOKUP(J$1,'geocodes & mnemonic list'!$I:$J,2,FALSE)=0,"", VLOOKUP(J$1,'geocodes & mnemonic list'!$I:$J,2,FALSE)) -> FET | K2: =IF(VLOOKUP(K$1,'geocodes & mnemonic list'!$I:$J,2,FALSE)=0,"", VLOOKUP(K$1,'geocodes & mnemonic list'!$I:$J,2,FALSE)) -> FCPIU | ... BA2: =IF(VLOOKUP(BA$1,'geocodes & mnemonic list'!$I:$J,2,FALSE)=0,"", VLOOKUP(BA$1,'geocodes & mnemonic list'!$I:$J,2,FALSE))
D3: =VLOOKUP(D$2,'geocodes & mnemonic list'!$J:$K,2,FALSE) -> Baseline Scenario (August 2025): Households: Total, (Ths. #, NSA) | E3: =VLOOKUP(E$2,'geocodes & mnemonic list'!$J:$K,2,FALSE) -> Baseline Scenario (August 2025): Population: Ages 20-24, (Ths. #, NSA) | F3: =VLOOKUP(F$2,'geocodes & mnemonic list'!$J:$K,2,FALSE) -> Baseline Scenario (August 2025): Population: Ages 25-29, (Ths. #, NSA) | G3: =VLOOKUP(G$2,'geocodes & mnemonic list'!$J:$K,2,FALSE) -> Baseline Scenario (August 2025): Population: Ages 30-34, (Ths. #, NSA) | H3: =VLOOKUP(H$2,'geocodes & mnemonic list'!$J:$K,2,FALSE) -> Baseline Scenario (August 2025): Population: Total, (Ths. #, NSA) | I3: =VLOOKUP(I$2,'geocodes & mnemonic list'!$J:$K,2,FALSE) -> Baseline Scenario (August 2025): Income: Median Household, (USD, SAAR) | J3: =VLOOKUP(J$2,'geocodes & mnemonic list'!$J:$K,2,FALSE) -> Baseline Scenario (August 2025): Employment: Total Non-Agricultural, (Ths. #, SA) | K3: =VLOOKUP(K$2,'geocodes & mnemonic list'!$J:$K,2,FALSE) -> Baseline Scenario (August 2025): CPI: Total - All Urban Consumers, (Index 1982-84=100, SA) | ... P3: =VLOOKUP(P$2,'geocodes & mnemonic list'!$J:$K,2,FALSE) -> Baseline Scenario (August 2025): Existing Single-Family Home Price: Median, (Ths. USD, SA)
B4: Market: | C4: geocodes:
A5: 1 | B5: =IF(VLOOKUP($A5,'geocodes & mnemonic list'!$A$5:$D$55,2,FALSE)<>"",VLOOKUP($A5,'geocodes & mnemonic list'!$A$5:$D$55,2,FALSE),"") -> Denver | C5: =IF(VLOOKUP($A5,'geocodes & mnemonic list'!$A$5:$E$104,5,FALSE)=0,"",VLOOKUP($A5,'geocodes & mnemonic list'!$A$5:$E$104,5,FALSE)) -> IUSA_MDEN | D5: =IF(AND($C5<>"",D$2<>""),D$2&"."&$C5,"") -> FHHOLDQ.IUSA_MDEN | E5: =IF(AND($C5<>"",E$2<>""),E$2&"."&$C5,"") -> FPOP2024Q.IUSA_MDEN | F5: =IF(AND($C5<>"",F$2<>""),F$2&"."&$C5,"") -> FPOP2529Q.IUSA_MDEN | G5: =IF(AND($C5<>"",G$2<>""),G$2&"."&$C5,"") -> FPOP3034Q.IUSA_MDEN | H5: =IF(AND($C5<>"",H$2<>""),H$2&"."&$C5,"") -> FPOPQ.IUSA_MDEN | I5: =IF(AND($C5<>"",I$2<>""),I$2&"."&$C5,"") -> FYHHMEDQ.IUSA_MDEN | J5: =IF(AND($C5<>"",J$2<>""),J$2&"."&$C5,"") -> FET.IUSA_MDEN | K5: =IF(AND($C5<>"",K$2<>""),K$2&"."&$C5,"") -> FCPIU.IUSA_MDEN | ... BA5: =IF(AND($C5<>"",BA$2<>""),BA$2&"."&$C5,"")
A6: 2 | B6: =IF(VLOOKUP($A6,'geocodes & mnemonic list'!$A$5:$D$55,2,FALSE)<>"",VLOOKUP($A6,'geocodes & mnemonic list'!$A$5:$D$55,2,FALSE),"") -> Los Angeles | C6: =IF(VLOOKUP($A6,'geocodes & mnemonic list'!$A$5:$E$104,5,FALSE)=0,"",VLOOKUP($A6,'geocodes & mnemonic list'!$A$5:$E$104,5,FALSE)) -> IUSA_DMLOS | D6: =IF(AND($C6<>"",D$2<>""),D$2&"."&$C6,"") -> FHHOLDQ.IUSA_DMLOS | E6: =IF(AND($C6<>"",E$2<>""),E$2&"."&$C6,"") -> FPOP2024Q.IUSA_DMLOS | F6: =IF(AND($C6<>"",F$2<>""),F$2&"."&$C6,"") -> FPOP2529Q.IUSA_DMLOS | G6: =IF(AND($C6<>"",G$2<>""),G$2&"."&$C6,"") -> FPOP3034Q.IUSA_DMLOS | H6: =IF(AND($C6<>"",H$2<>""),H$2&"."&$C6,"") -> FPOPQ.IUSA_DMLOS | I6: =IF(AND($C6<>"",I$2<>""),I$2&"."&$C6,"") -> FYHHMEDQ.IUSA_DMLOS | J6: =IF(AND($C6<>"",J$2<>""),J$2&"."&$C6,"") -> FET.IUSA_DMLOS | K6: =IF(AND($C6<>"",K$2<>""),K$2&"."&$C6,"") -> FCPIU.IUSA_DMLOS | ... BA6: =IF(AND($C6<>"",BA$2<>""),BA$2&"."&$C6,"")
A7: 3 | B7: =IF(VLOOKUP($A7,'geocodes & mnemonic list'!$A$5:$D$55,2,FALSE)<>"",VLOOKUP($A7,'geocodes & mnemonic list'!$A$5:$D$55,2,FALSE),"") -> Oakland-East Bay | C7: =IF(VLOOKUP($A7,'geocodes & mnemonic list'!$A$5:$E$104,5,FALSE)=0,"",VLOOKUP($A7,'geocodes & mnemonic list'!$A$5:$E$104,5,FALSE)) -> IUSA_DMOAK | D7: =IF(AND($C7<>"",D$2<>""),D$2&"."&$C7,"") -> FHHOLDQ.IUSA_DMOAK | E7: =IF(AND($C7<>"",E$2<>""),E$2&"."&$C7,"") -> FPOP2024Q.IUSA_DMOAK | F7: =IF(AND($C7<>"",F$2<>""),F$2&"."&$C7,"") -> FPOP2529Q.IUSA_DMOAK | G7: =IF(AND($C7<>"",G$2<>""),G$2&"."&$C7,"") -> FPOP3034Q.IUSA_DMOAK | H7: =IF(AND($C7<>"",H$2<>""),H$2&"."&$C7,"") -> FPOPQ.IUSA_DMOAK | I7: =IF(AND($C7<>"",I$2<>""),I$2&"."&$C7,"") -> FYHHMEDQ.IUSA_DMOAK | J7: =IF(AND($C7<>"",J$2<>""),J$2&"."&$C7,"") -> FET.IUSA_DMOAK | K7: =IF(AND($C7<>"",K$2<>""),K$2&"."&$C7,"") -> FCPIU.IUSA_DMOAK | ... BA7: =IF(AND($C7<>"",BA$2<>""),BA$2&"."&$C7,"")
A8: 4 | B8: =IF(VLOOKUP($A8,'geocodes & mnemonic list'!$A$5:$D$55,2,FALSE)<>"",VLOOKUP($A8,'geocodes & mnemonic list'!$A$5:$D$55,2,FALSE),"") -> Orange County | C8: =IF(VLOOKUP($A8,'geocodes & mnemonic list'!$A$5:$E$104,5,FALSE)=0,"",VLOOKUP($A8,'geocodes & mnemonic list'!$A$5:$E$104,5,FALSE)) -> IUSA_DMANA | D8: =IF(AND($C8<>"",D$2<>""),D$2&"."&$C8,"") -> FHHOLDQ.IUSA_DMANA | E8: =IF(AND($C8<>"",E$2<>""),E$2&"."&$C8,"") -> FPOP2024Q.IUSA_DMANA | F8: =IF(AND($C8<>"",F$2<>""),F$2&"."&$C8,"") -> FPOP2529Q.IUSA_DMANA | G8: =IF(AND($C8<>"",G$2<>""),G$2&"."&$C8,"") -> FPOP3034Q.IUSA_DMANA | H8: =IF(AND($C8<>"",H$2<>""),H$2&"."&$C8,"") -> FPOPQ.IUSA_DMANA | I8: =IF(AND($C8<>"",I$2<>""),I$2&"."&$C8,"") -> FYHHMEDQ.IUSA_DMANA | J8: =IF(AND($C8<>"",J$2<>""),J$2&"."&$C8,"") -> FET.IUSA_DMANA | K8: =IF(AND($C8<>"",K$2<>""),K$2&"."&$C8,"") -> FCPIU.IUSA_DMANA | ... BA8: =IF(AND($C8<>"",BA$2<>""),BA$2&"."&$C8,"")
A9: 5 | B9: =IF(VLOOKUP($A9,'geocodes & mnemonic list'!$A$5:$D$55,2,FALSE)<>"",VLOOKUP($A9,'geocodes & mnemonic list'!$A$5:$D$55,2,FALSE),"") -> Portland | C9: =IF(VLOOKUP($A9,'geocodes & mnemonic list'!$A$5:$E$104,5,FALSE)=0,"",VLOOKUP($A9,'geocodes & mnemonic list'!$A$5:$E$104,5,FALSE)) -> IUSA_MPOT | D9: =IF(AND($C9<>"",D$2<>""),D$2&"."&$C9,"") -> FHHOLDQ.IUSA_MPOT | E9: =IF(AND($C9<>"",E$2<>""),E$2&"."&$C9,"") -> FPOP2024Q.IUSA_MPOT | F9: =IF(AND($C9<>"",F$2<>""),F$2&"."&$C9,"") -> FPOP2529Q.IUSA_MPOT | G9: =IF(AND($C9<>"",G$2<>""),G$2&"."&$C9,"") -> FPOP3034Q.IUSA_MPOT | H9: =IF(AND($C9<>"",H$2<>""),H$2&"."&$C9,"") -> FPOPQ.IUSA_MPOT | I9: =IF(AND($C9<>"",I$2<>""),I$2&"."&$C9,"") -> FYHHMEDQ.IUSA_MPOT | J9: =IF(AND($C9<>"",J$2<>""),J$2&"."&$C9,"") -> FET.IUSA_MPOT | K9: =IF(AND($C9<>"",K$2<>""),K$2&"."&$C9,"") -> FCPIU.IUSA_MPOT | ... BA9: =IF(AND($C9<>"",BA$2<>""),BA$2&"."&$C9,"")
A10: 6 | B10: =IF(VLOOKUP($A10,'geocodes & mnemonic list'!$A$5:$D$55,2,FALSE)<>"",VLOOKUP($A10,'geocodes & mnemonic list'!$A$5:$D$55,2,FALSE),"") -> San Jose | C10: =IF(VLOOKUP($A10,'geocodes & mnemonic list'!$A$5:$E$104,5,FALSE)=0,"",VLOOKUP($A10,'geocodes & mnemonic list'!$A$5:$E$104,5,FALSE)) -> IUSA_MSAJ | D10: =IF(AND($C10<>"",D$2<>""),D$2&"."&$C10,"") -> FHHOLDQ.IUSA_MSAJ | E10: =IF(AND($C10<>"",E$2<>""),E$2&"."&$C10,"") -> FPOP2024Q.IUSA_MSAJ | F10: =IF(AND($C10<>"",F$2<>""),F$2&"."&$C10,"") -> FPOP2529Q.IUSA_MSAJ | G10: =IF(AND($C10<>"",G$2<>""),G$2&"."&$C10,"") -> FPOP3034Q.IUSA_MSAJ | H10: =IF(AND($C10<>"",H$2<>""),H$2&"."&$C10,"") -> FPOPQ.IUSA_MSAJ | I10: =IF(AND($C10<>"",I$2<>""),I$2&"."&$C10,"") -> FYHHMEDQ.IUSA_MSAJ | J10: =IF(AND($C10<>"",J$2<>""),J$2&"."&$C10,"") -> FET.IUSA_MSAJ | K10: =IF(AND($C10<>"",K$2<>""),K$2&"."&$C10,"") -> FCPIU.IUSA_MSAJ | ... BA10: =IF(AND($C10<>"",BA$2<>""),BA$2&"."&$C10,"")
A11: 7 | B11: =IF(VLOOKUP($A11,'geocodes & mnemonic list'!$A$5:$D$55,2,FALSE)<>"",VLOOKUP($A11,'geocodes & mnemonic list'!$A$5:$D$55,2,FALSE),"") -> San Diego | C11: =IF(VLOOKUP($A11,'geocodes & mnemonic list'!$A$5:$E$104,5,FALSE)=0,"",VLOOKUP($A11,'geocodes & mnemonic list'!$A$5:$E$104,5,FALSE)) -> IUSA_MSAN | D11: =IF(AND($C11<>"",D$2<>""),D$2&"."&$C11,"") -> FHHOLDQ.IUSA_MSAN | E11: =IF(AND($C11<>"",E$2<>""),E$2&"."&$C11,"") -> FPOP2024Q.IUSA_MSAN | F11: =IF(AND($C11<>"",F$2<>""),F$2&"."&$C11,"") -> FPOP2529Q.IUSA_MSAN | G11: =IF(AND($C11<>"",G$2<>""),G$2&"."&$C11,"") -> FPOP3034Q.IUSA_MSAN | H11: =IF(AND($C11<>"",H$2<>""),H$2&"."&$C11,"") -> FPOPQ.IUSA_MSAN | I11: =IF(AND($C11<>"",I$2<>""),I$2&"."&$C11,"") -> FYHHMEDQ.IUSA_MSAN | J11: =IF(AND($C11<>"",J$2<>""),J$2&"."&$C11,"") -> FET.IUSA_MSAN | K11: =IF(AND($C11<>"",K$2<>""),K$2&"."&$C11,"") -> FCPIU.IUSA_MSAN | ... BA11: =IF(AND($C11<>"",BA$2<>""),BA$2&"."&$C11,"")
A12: 8 | B12: =IF(VLOOKUP($A12,'geocodes & mnemonic list'!$A$5:$D$55,2,FALSE)<>"",VLOOKUP($A12,'geocodes & mnemonic list'!$A$5:$D$55,2,FALSE),"") -> Ventura County | C12: =IF(VLOOKUP($A12,'geocodes & mnemonic list'!$A$5:$E$104,5,FALSE)=0,"",VLOOKUP($A12,'geocodes & mnemonic list'!$A$5:$E$104,5,FALSE)) -> IUSA_MOXN | D12: =IF(AND($C12<>"",D$2<>""),D$2&"."&$C12,"") -> FHHOLDQ.IUSA_MOXN | E12: =IF(AND($C12<>"",E$2<>""),E$2&"."&$C12,"") -> FPOP2024Q.IUSA_MOXN | F12: =IF(AND($C12<>"",F$2<>""),F$2&"."&$C12,"") -> FPOP2529Q.IUSA_MOXN | G12: =IF(AND($C12<>"",G$2<>""),G$2&"."&$C12,"") -> FPOP3034Q.IUSA_MOXN | H12: =IF(AND($C12<>"",H$2<>""),H$2&"."&$C12,"") -> FPOPQ.IUSA_MOXN | I12: =IF(AND($C12<>"",I$2<>""),I$2&"."&$C12,"") -> FYHHMEDQ.IUSA_MOXN | J12: =IF(AND($C12<>"",J$2<>""),J$2&"."&$C12,"") -> FET.IUSA_MOXN | K12: =IF(AND($C12<>"",K$2<>""),K$2&"."&$C12,"") -> FCPIU.IUSA_MOXN | ... BA12: =IF(AND($C12<>"",BA$2<>""),BA$2&"."&$C12,"")
A13: 9 | B13: =IF(VLOOKUP($A13,'geocodes & mnemonic list'!$A$5:$D$55,2,FALSE)<>"",VLOOKUP($A13,'geocodes & mnemonic list'!$A$5:$D$55,2,FALSE),"") -> Fairfield County | C13: =IF(VLOOKUP($A13,'geocodes & mnemonic list'!$A$5:$E$104,5,FALSE)=0,"",VLOOKUP($A13,'geocodes & mnemonic list'!$A$5:$E$104,5,FALSE)) -> IUSA_MBSD | D13: =IF(AND($C13<>"",D$2<>""),D$2&"."&$C13,"") -> FHHOLDQ.IUSA_MBSD | E13: =IF(AND($C13<>"",E$2<>""),E$2&"."&$C13,"") -> FPOP2024Q.IUSA_MBSD | F13: =IF(AND($C13<>"",F$2<>""),F$2&"."&$C13,"") -> FPOP2529Q.IUSA_MBSD | G13: =IF(AND($C13<>"",G$2<>""),G$2&"."&$C13,"") -> FPOP3034Q.IUSA_MBSD | H13: =IF(AND($C13<>"",H$2<>""),H$2&"."&$C13,"") -> FPOPQ.IUSA_MBSD | I13: =IF(AND($C13<>"",I$2<>""),I$2&"."&$C13,"") -> FYHHMEDQ.IUSA_MBSD | J13: =IF(AND($C13<>"",J$2<>""),J$2&"."&$C13,"") -> FET.IUSA_MBSD | K13: =IF(AND($C13<>"",K$2<>""),K$2&"."&$C13,"") -> FCPIU.IUSA_MBSD | ... BA13: =IF(AND($C13<>"",BA$2<>""),BA$2&"."&$C13,"")
A14: 10 | B14: =IF(VLOOKUP($A14,'geocodes & mnemonic list'!$A$5:$D$55,2,FALSE)<>"",VLOOKUP($A14,'geocodes & mnemonic list'!$A$5:$D$55,2,FALSE),"") -> Boston | C14: =IF(VLOOKUP($A14,'geocodes & mnemonic list'!$A$5:$E$104,5,FALSE)=0,"",VLOOKUP($A14,'geocodes & mnemonic list'!$A$5:$E$104,5,FALSE)) -> IUSA_MBOS | D14: =IF(AND($C14<>"",D$2<>""),D$2&"."&$C14,"") -> FHHOLDQ.IUSA_MBOS | E14: =IF(AND($C14<>"",E$2<>""),E$2&"."&$C14,"") -> FPOP2024Q.IUSA_MBOS | F14: =IF(AND($C14<>"",F$2<>""),F$2&"."&$C14,"") -> FPOP2529Q.IUSA_MBOS | G14: =IF(AND($C14<>"",G$2<>""),G$2&"."&$C14,"") -> FPOP3034Q.IUSA_MBOS | H14: =IF(AND($C14<>"",H$2<>""),H$2&"."&$C14,"") -> FPOPQ.IUSA_MBOS | I14: =IF(AND($C14<>"",I$2<>""),I$2&"."&$C14,"") -> FYHHMEDQ.IUSA_MBOS | J14: =IF(AND($C14<>"",J$2<>""),J$2&"."&$C14,"") -> FET.IUSA_MBOS | K14: =IF(AND($C14<>"",K$2<>""),K$2&"."&$C14,"") -> FCPIU.IUSA_MBOS | ... BA14: =IF(AND($C14<>"",BA$2<>""),BA$2&"."&$C14,"")
A15: 11 | B15: =IF(VLOOKUP($A15,'geocodes & mnemonic list'!$A$5:$D$55,2,FALSE)<>"",VLOOKUP($A15,'geocodes & mnemonic list'!$A$5:$D$55,2,FALSE),"") -> New York Metro | C15: =IF(VLOOKUP($A15,'geocodes & mnemonic list'!$A$5:$E$104,5,FALSE)=0,"",VLOOKUP($A15,'geocodes & mnemonic list'!$A$5:$E$104,5,FALSE)) -> IUSA_DMNWY | D15: =IF(AND($C15<>"",D$2<>""),D$2&"."&$C15,"") -> FHHOLDQ.IUSA_DMNWY | E15: =IF(AND($C15<>"",E$2<>""),E$2&"."&$C15,"") -> FPOP2024Q.IUSA_DMNWY | F15: =IF(AND($C15<>"",F$2<>""),F$2&"."&$C15,"") -> FPOP2529Q.IUSA_DMNWY | G15: =IF(AND($C15<>"",G$2<>""),G$2&"."&$C15,"") -> FPOP3034Q.IUSA_DMNWY | H15: =IF(AND($C15<>"",H$2<>""),H$2&"."&$C15,"") -> FPOPQ.IUSA_DMNWY | I15: =IF(AND($C15<>"",I$2<>""),I$2&"."&$C15,"") -> FYHHMEDQ.IUSA_DMNWY | J15: =IF(AND($C15<>"",J$2<>""),J$2&"."&$C15,"") -> FET.IUSA_DMNWY | K15: =IF(AND($C15<>"",K$2<>""),K$2&"."&$C15,"") -> FCPIU.IUSA_DMNWY | ... BA15: =IF(AND($C15<>"",BA$2<>""),BA$2&"."&$C15,"")
A16: 12 | B16: =IF(VLOOKUP($A16,'geocodes & mnemonic list'!$A$5:$D$55,2,FALSE)<>"",VLOOKUP($A16,'geocodes & mnemonic list'!$A$5:$D$55,2,FALSE),"") -> Northern New Jersey | C16: =IF(VLOOKUP($A16,'geocodes & mnemonic list'!$A$5:$E$104,5,FALSE)=0,"",VLOOKUP($A16,'geocodes & mnemonic list'!$A$5:$E$104,5,FALSE)) -> IUSA_DMNEK | D16: =IF(AND($C16<>"",D$2<>""),D$2&"."&$C16,"") -> FHHOLDQ.IUSA_DMNEK | E16: =IF(AND($C16<>"",E$2<>""),E$2&"."&$C16,"") -> FPOP2024Q.IUSA_DMNEK | F16: =IF(AND($C16<>"",F$2<>""),F$2&"."&$C16,"") -> FPOP2529Q.IUSA_DMNEK | G16: =IF(AND($C16<>"",G$2<>""),G$2&"."&$C16,"") -> FPOP3034Q.IUSA_DMNEK | H16: =IF(AND($C16<>"",H$2<>""),H$2&"."&$C16,"") -> FPOPQ.IUSA_DMNEK | I16: =IF(AND($C16<>"",I$2<>""),I$2&"."&$C16,"") -> FYHHMEDQ.IUSA_DMNEK | J16: =IF(AND($C16<>"",J$2<>""),J$2&"."&$C16,"") -> FET.IUSA_DMNEK | K16: =IF(AND($C16<>"",K$2<>""),K$2&"."&$C16,"") -> FCPIU.IUSA_DMNEK | ... BA16: =IF(AND($C16<>"",BA$2<>""),BA$2&"."&$C16,"")
... A54: 50 | B54: =IF(VLOOKUP($A54,'geocodes & mnemonic list'!$A$5:$D$55,2,FALSE)<>"",VLOOKUP($A54,'geocodes & mnemonic list'!$A$5:$D$55,2,FALSE),"") | C54: =IF(VLOOKUP($A54,'geocodes & mnemonic list'!$A$5:$E$104,5,FALSE)=0,"",VLOOKUP($A54,'geocodes & mnemonic list'!$A$5:$E$104,5,FALSE)) | D54: =IF(AND($C54<>"",D$2<>""),D$2&"."&$C54,"") | E54: =IF(AND($C54<>"",E$2<>""),E$2&"."&$C54,"") | F54: =IF(AND($C54<>"",F$2<>""),F$2&"."&$C54,"") | G54: =IF(AND($C54<>"",G$2<>""),G$2&"."&$C54,"") | H54: =IF(AND($C54<>"",H$2<>""),H$2&"."&$C54,"") | I54: =IF(AND($C54<>"",I$2<>""),I$2&"."&$C54,"") | J54: =IF(AND($C54<>"",J$2<>""),J$2&"."&$C54,"") | K54: =IF(AND($C54<>"",K$2<>""),K$2&"."&$C54,"") | ... BA54: =IF(AND($C54<>"",BA$2<>""),BA$2&"."&$C54,"")

Sheet Double Geocode Compiler
A1: ~ FPOPQ is the weighting factor for weighted average aggregations | E1: 1 | F1: 2 | G1: 3 | H1: 4 | I1: 5 | J1: 6 | K1: 7 | L1: 8 | M1: 9 | N1: 10 | O1: 11 | P1: 12 | Q1: 13 | R1: 14 | S1: 15 | T1: 16 | U1: 17 | V1: 18 | W1: 19 | X1: 20 | Y1: 21 | Z1: 22 | AA1: 23 | AB1: 24 | AC1: 25 | AD1: 26 | AE1: 27 | AF1: 28 | AG1: 29 | AH1: 30 | AI1: 31 | AJ1: 32 | AK1: 33 | AL1: 34 | AM1: 35 | AN1: 36 | AO1: 37 | AP1: 38 | AQ1: 39 | AR1: 40 | AS1: 41 | AT1: 42 | AU1: 43 | AV1: 44 | AW1: 45 | AX1: 46 | AY1: 47 | AZ1: 48 | BA1: 49 | BB1: 50
D2: Mnemonics: | E2: =IF(VLOOKUP(E$1,'geocodes & mnemonic list'!$I:$J,2,FALSE)=0,"", VLOOKUP(E$1,'geocodes & mnemonic list'!$I:$J,2,FALSE)) -> FHHOLDQ | F2: =IF(VLOOKUP(F$1,'geocodes & mnemonic list'!$I:$J,2,FALSE)=0,"", VLOOKUP(F$1,'geocodes & mnemonic list'!$I:$J,2,FALSE)) -> FPOP2024Q | G2: =IF(VLOOKUP(G$1,'geocodes & mnemonic list'!$I:$J,2,FALSE)=0,"", VLOOKUP(G$1,'geocodes & mnemonic list'!$I:$J,2,FALSE)) -> FPOP2529Q | H2: =IF(VLOOKUP(H$1,'geocodes & mnemonic list'!$I:$J,2,FALSE)=0,"", VLOOKUP(H$1,'geocodes & mnemonic list'!$I:$J,2,FALSE)) -> FPOP3034Q | I2: =IF(VLOOKUP(I$1,'geocodes & mnemonic list'!$I:$J,2,FALSE)=0,"", VLOOKUP(I$1,'geocodes & mnemonic list'!$I:$J,2,FALSE)) -> FPOPQ | J2: =IF(VLOOKUP(J$1,'geocodes & mnemonic list'!$I:$J,2,FALSE)=0,"", VLOOKUP(J$1,'geocodes & mnemonic list'!$I:$J,2,FALSE)) -> FYHHMEDQ | K2: =IF(VLOOKUP(K$1,'geocodes & mnemonic list'!$I:$J,2,FALSE)=0,"", VLOOKUP(K$1,'geocodes & mnemonic list'!$I:$J,2,FALSE)) -> FET | L2: =IF(VLOOKUP(L$1,'geocodes & mnemonic list'!$I:$J,2,FALSE)=0,"", VLOOKUP(L$1,'geocodes & mnemonic list'!$I:$J,2,FALSE)) -> FCPIU | ... BB2: =IF(VLOOKUP(BB$1,'geocodes & mnemonic list'!$I:$J,2,FALSE)=0,"", VLOOKUP(BB$1,'geocodes & mnemonic list'!$I:$J,2,FALSE))
A3: *Enter list number next to | E3: =VLOOKUP(E$2,'geocodes & mnemonic list'!$J:$K,2,FALSE) -> Baseline Scenario (August 2025): Households: Total, (Ths. #, NSA) | F3: =VLOOKUP(F$2,'geocodes & mnemonic list'!$J:$K,2,FALSE) -> Baseline Scenario (August 2025): Population: Ages 20-24, (Ths. #, NSA) | G3: =VLOOKUP(G$2,'geocodes & mnemonic list'!$J:$K,2,FALSE) -> Baseline Scenario (August 2025): Population: Ages 25-29, (Ths. #, NSA) | H3: =VLOOKUP(H$2,'geocodes & mnemonic list'!$J:$K,2,FALSE) -> Baseline Scenario (August 2025): Population: Ages 30-34, (Ths. #, NSA) | I3: =VLOOKUP(I$2,'geocodes & mnemonic list'!$J:$K,2,FALSE) -> Baseline Scenario (August 2025): Population: Total, (Ths. #, NSA) | J3: =VLOOKUP(J$2,'geocodes & mnemonic list'!$J:$K,2,FALSE) -> Baseline Scenario (August 2025): Income: Median Household, (USD, SAAR) | K3: =VLOOKUP(K$2,'geocodes & mnemonic list'!$J:$K,2,FALSE) -> Baseline Scenario (August 2025): Employment: Total Non-Agricultural, (Ths. #, SA) | L3: =VLOOKUP(L$2,'geocodes & mnemonic list'!$J:$K,2,FALSE) -> Baseline Scenario (August 2025): CPI: Total - All Urban Consumers, (Index 1982-84=100, SA) | ... Q3: =VLOOKUP(Q$2,'geocodes & mnemonic list'!$J:$K,2,FALSE) -> Baseline Scenario (August 2025): Existing Single-Family Home Price: Median, (Ths. USD, SA)
D4: Aggregation Method: | E4: =VLOOKUP(E2,'geocodes & mnemonic list'!$J:$L,3,FALSE) -> sum | F4: =VLOOKUP(F2,'geocodes & mnemonic list'!$J:$L,3,FALSE) -> sum | G4: =VLOOKUP(G2,'geocodes & mnemonic list'!$J:$L,3,FALSE) -> sum | H4: =VLOOKUP(H2,'geocodes & mnemonic list'!$J:$L,3,FALSE) -> sum | I4: =VLOOKUP(I2,'geocodes & mnemonic list'!$J:$L,3,FALSE) -> sum | J4: =VLOOKUP(J2,'geocodes & mnemonic list'!$J:$L,3,FALSE) -> weighted avg | K4: =VLOOKUP(K2,'geocodes & mnemonic list'!$J:$L,3,FALSE) -> sum | L4: =VLOOKUP(L2,'geocodes & mnemonic list'!$J:$L,3,FALSE) -> weighted avg | ... Q4: =VLOOKUP(Q2,'geocodes & mnemonic list'!$J:$L,3,FALSE) -> weighted avg
B5: Market: | C5: 1st geocode | D5: 2nd geocode
A6: 28 | B6: Seattle | C6: =VLOOKUP($B6&" 1", 'geocodes & mnemonic list'!$B:$E,4,FALSE) -> IUSA_DMEVE | D6: =VLOOKUP($B6&" 2", 'geocodes & mnemonic list'!$B:$E,4,FALSE) -> IUSA_DMSEB | E6: =IF(AND($D6<>"",E$2<>""), E$2&"."&$D6&"+"&E$2&"."&$C6,"") -> FHHOLDQ.IUSA_DMSEB+FHHOLDQ.IUSA_DMEVE | F6: =IF(AND($D6<>"",F$2<>""), F$2&"."&$D6&"+"&F$2&"."&$C6,"") -> FPOP2024Q.IUSA_DMSEB+FPOP2024Q.IUSA_DMEVE | G6: =IF(AND($D6<>"",G$2<>""), G$2&"."&$D6&"+"&G$2&"."&$C6,"") -> FPOP2529Q.IUSA_DMSEB+FPOP2529Q.IUSA_DMEVE | H6: =IF(AND($D6<>"",H$2<>""), H$2&"."&$D6&"+"&H$2&"."&$C6,"") -> FPOP3034Q.IUSA_DMSEB+FPOP3034Q.IUSA_DMEVE | I6: =IF(AND($D6<>"",I$2<>""), I$2&"."&$D6&"+"&I$2&"."&$C6,"") -> FPOPQ.IUSA_DMSEB+FPOPQ.IUSA_DMEVE | J6: =IF(AND($D6<>"",J$2<>""), "("&$I$2&"."&$D6&"*"&J$2&"."&$D6&" + "&$I$2&"."&$C6&"*"&J$2&"."&$C6&") / ("&$I$2&"."&$D6&" + "&$I$2&"."&$C6&")","") -> (FPOPQ.IUSA_DMSEB*FYHHMEDQ.IUSA_DMSEB + FPOPQ.IUSA_DMEVE*FYHHMEDQ.IUSA_DMEVE) / (FPOPQ.IUSA_DMSEB + FPOPQ.IUSA_DMEVE) | K6: =IF(AND($D6<>"",K$2<>""), K$2&"."&$D6&"+"&K$2&"."&$C6,"") -> FET.IUSA_DMSEB+FET.IUSA_DMEVE | L6: =IF(AND($D6<>"",L$2<>""), "("&$I$2&"."&$D6&"*"&L$2&"."&$D6&" + "&$I$2&"."&$C6&"*"&L$2&"."&$C6&") / ("&$I$2&"."&$D6&" + "&$I$2&"."&$C6&")","") -> (FPOPQ.IUSA_DMSEB*FCPIU.IUSA_DMSEB + FPOPQ.IUSA_DMEVE*FCPIU.IUSA_DMEVE) / (FPOPQ.IUSA_DMSEB + FPOPQ.IUSA_DMEVE) | M6: =IF(AND($D6<>"",M$2<>""), M$2&"."&$D6&"+"&M$2&"."&$C6,"") -> FGDP$Q.IUSA_DMSEB+FGDP$Q.IUSA_DMEVE | N6: =IF(AND($D6<>"",N$2<>""), N$2&"."&$D6&"+"&N$2&"."&$C6,"") -> FHPNR.IUSA_DMSEB+FHPNR.IUSA_DMEVE | O6: =IF(AND($D6<>"",O$2<>""), O$2&"."&$D6&"+"&O$2&"."&$C6,"") -> FHPNM.IUSA_DMSEB+FHPNM.IUSA_DMEVE | P6: =IF(AND($D6<>"",P$2<>""), P$2&"."&$D6&"+"&P$2&"."&$C6,"") -> FHX1.IUSA_DMSEB+FHX1.IUSA_DMEVE | Q6: =IF(AND($D6<>"",Q$2<>""), "("&$I$2&"."&$D6&"*"&Q$2&"."&$D6&" + "&$I$2&"."&$C6&"*"&Q$2&"."&$C6&") / ("&$I$2&"."&$D6&" + "&$I$2&"."&$C6&")","") -> (FPOPQ.IUSA_DMSEB*FHX1MED.IUSA_DMSEB + FPOPQ.IUSA_DMEVE*FHX1MED.IUSA_DMEVE) / (FPOPQ.IUSA_DMSEB + FPOPQ.IUSA_DMEVE)
A7: 29 | B7: San Francisco | C7: =VLOOKUP($B7&" 1", 'geocodes & mnemonic list'!$B:$E,4,FALSE) -> IUSA_DMSAF | D7: =VLOOKUP($B7&" 2", 'geocodes & mnemonic list'!$B:$E,4,FALSE) -> IUSA_DMSRF | E7: =IF(AND($D7<>"",E$2<>""), E$2&"."&$D7&"+"&E$2&"."&$C7,"") -> FHHOLDQ.IUSA_DMSRF+FHHOLDQ.IUSA_DMSAF | F7: =IF(AND($D7<>"",F$2<>""), F$2&"."&$D7&"+"&F$2&"."&$C7,"") -> FPOP2024Q.IUSA_DMSRF+FPOP2024Q.IUSA_DMSAF | G7: =IF(AND($D7<>"",G$2<>""), G$2&"."&$D7&"+"&G$2&"."&$C7,"") -> FPOP2529Q.IUSA_DMSRF+FPOP2529Q.IUSA_DMSAF | H7: =IF(AND($D7<>"",H$2<>""), H$2&"."&$D7&"+"&H$2&"."&$C7,"") -> FPOP3034Q.IUSA_DMSRF+FPOP3034Q.IUSA_DMSAF | I7: =IF(AND($D7<>"",I$2<>""), I$2&"."&$D7&"+"&I$2&"."&$C7,"") -> FPOPQ.IUSA_DMSRF+FPOPQ.IUSA_DMSAF | J7: =IF(AND($D7<>"",J$2<>""), "("&$I$2&"."&$D7&"*"&J$2&"."&$D7&" + "&$I$2&"."&$C7&"*"&J$2&"."&$C7&") / ("&$I$2&"."&$D7&" + "&$I$2&"."&$C7&")","") -> (FPOPQ.IUSA_DMSRF*FYHHMEDQ.IUSA_DMSRF + FPOPQ.IUSA_DMSAF*FYHHMEDQ.IUSA_DMSAF) / (FPOPQ.IUSA_DMSRF + FPOPQ.IUSA_DMSAF) | K7: =IF(AND($D7<>"",K$2<>""), K$2&"."&$D7&"+"&K$2&"."&$C7,"") -> FET.IUSA_DMSRF+FET.IUSA_DMSAF | L7: =IF(AND($D7<>"",L$2<>""), "("&$I$2&"."&$D7&"*"&L$2&"."&$D7&" + "&$I$2&"."&$C7&"*"&L$2&"."&$C7&") / ("&$I$2&"."&$D7&" + "&$I$2&"."&$C7&")","") -> (FPOPQ.IUSA_DMSRF*FCPIU.IUSA_DMSRF + FPOPQ.IUSA_DMSAF*FCPIU.IUSA_DMSAF) / (FPOPQ.IUSA_DMSRF + FPOPQ.IUSA_DMSAF) | M7: =IF(AND($D7<>"",M$2<>""), M$2&"."&$D7&"+"&M$2&"."&$C7,"") -> FGDP$Q.IUSA_DMSRF+FGDP$Q.IUSA_DMSAF | N7: =IF(AND($D7<>"",N$2<>""), N$2&"."&$D7&"+"&N$2&"."&$C7,"") -> FHPNR.IUSA_DMSRF+FHPNR.IUSA_DMSAF | O7: =IF(AND($D7<>"",O$2<>""), O$2&"."&$D7&"+"&O$2&"."&$C7,"") -> FHPNM.IUSA_DMSRF+FHPNM.IUSA_DMSAF | P7: =IF(AND($D7<>"",P$2<>""), P$2&"."&$D7&"+"&P$2&"."&$C7,"") -> FHX1.IUSA_DMSRF+FHX1.IUSA_DMSAF | Q7: =IF(AND($D7<>"",Q$2<>""), "("&$I$2&"."&$D7&"*"&Q$2&"."&$D7&" + "&$I$2&"."&$C7&"*"&Q$2&"."&$C7&") / ("&$I$2&"."&$D7&" + "&$I$2&"."&$C7&")","") -> (FPOPQ.IUSA_DMSRF*FHX1MED.IUSA_DMSRF + FPOPQ.IUSA_DMSAF*FHX1MED.IUSA_DMSAF) / (FPOPQ.IUSA_DMSRF + FPOPQ.IUSA_DMSAF)
A8: 30 | B8: Raleigh-Durham | C8: =VLOOKUP($B8&" 1", 'geocodes & mnemonic list'!$B:$E,4,FALSE) -> IUSA_MRAL | D8: =VLOOKUP($B8&" 2", 'geocodes & mnemonic list'!$B:$E,4,FALSE) -> IUSA_MDUR | E8: =IF(AND($D8<>"",E$2<>""), E$2&"."&$D8&"+"&E$2&"."&$C8,"") -> FHHOLDQ.IUSA_MDUR+FHHOLDQ.IUSA_MRAL | F8: =IF(AND($D8<>"",F$2<>""), F$2&"."&$D8&"+"&F$2&"."&$C8,"") -> FPOP2024Q.IUSA_MDUR+FPOP2024Q.IUSA_MRAL | G8: =IF(AND($D8<>"",G$2<>""), G$2&"."&$D8&"+"&G$2&"."&$C8,"") -> FPOP2529Q.IUSA_MDUR+FPOP2529Q.IUSA_MRAL | H8: =IF(AND($D8<>"",H$2<>""), H$2&"."&$D8&"+"&H$2&"."&$C8,"") -> FPOP3034Q.IUSA_MDUR+FPOP3034Q.IUSA_MRAL | I8: =IF(AND($D8<>"",I$2<>""), I$2&"."&$D8&"+"&I$2&"."&$C8,"") -> FPOPQ.IUSA_MDUR+FPOPQ.IUSA_MRAL | J8: =IF(AND($D8<>"",J$2<>""), "("&$I$2&"."&$D8&"*"&J$2&"."&$D8&" + "&$I$2&"."&$C8&"*"&J$2&"."&$C8&") / ("&$I$2&"."&$D8&" + "&$I$2&"."&$C8&")","") -> (FPOPQ.IUSA_MDUR*FYHHMEDQ.IUSA_MDUR + FPOPQ.IUSA_MRAL*FYHHMEDQ.IUSA_MRAL) / (FPOPQ.IUSA_MDUR + FPOPQ.IUSA_MRAL) | K8: =IF(AND($D8<>"",K$2<>""), K$2&"."&$D8&"+"&K$2&"."&$C8,"") -> FET.IUSA_MDUR+FET.IUSA_MRAL | L8: =IF(AND($D8<>"",L$2<>""), "("&$I$2&"."&$D8&"*"&L$2&"."&$D8&" + "&$I$2&"."&$C8&"*"&L$2&"."&$C8&") / ("&$I$2&"."&$D8&" + "&$I$2&"."&$C8&")","") -> (FPOPQ.IUSA_MDUR*FCPIU.IUSA_MDUR + FPOPQ.IUSA_MRAL*FCPIU.IUSA_MRAL) / (FPOPQ.IUSA_MDUR + FPOPQ.IUSA_MRAL) | M8: =IF(AND($D8<>"",M$2<>""), M$2&"."&$D8&"+"&M$2&"."&$C8,"") -> FGDP$Q.IUSA_MDUR+FGDP$Q.IUSA_MRAL | N8: =IF(AND($D8<>"",N$2<>""), N$2&"."&$D8&"+"&N$2&"."&$C8,"") -> FHPNR.IUSA_MDUR+FHPNR.IUSA_MRAL | O8: =IF(AND($D8<>"",O$2<>""), O$2&"."&$D8&"+"&O$2&"."&$C8,"") -> FHPNM.IUSA_MDUR+FHPNM.IUSA_MRAL | P8: =IF(AND($D8<>"",P$2<>""), P$2&"."&$D8&"+"&P$2&"."&$C8,"") -> FHX1.IUSA_MDUR+FHX1.IUSA_MRAL | Q8: =IF(AND($D8<>"",Q$2<>""), "("&$I$2&"."&$D8&"*"&Q$2&"."&$D8&" + "&$I$2&"."&$C8&"*"&Q$2&"."&$C8&") / ("&$I$2&"."&$D8&" + "&$I$2&"."&$C8&")","") -> (FPOPQ.IUSA_MDUR*FHX1MED.IUSA_MDUR + FPOPQ.IUSA_MRAL*FHX1MED.IUSA_MRAL) / (FPOPQ.IUSA_MDUR + FPOPQ.IUSA_MRAL)
A9: 31 | E9: =IF(AND($D9<>"",E$2<>""), E$2&"."&$D9&"+"&E$2&"."&$C9,"") | F9: =IF(AND($D9<>"",F$2<>""),F$2&"."&$D9,"") | G9: =IF(AND($D9<>"",G$2<>""),G$2&"."&$D9,"") | H9: =IF(AND($D9<>"",H$2<>""),H$2&"."&$D9,"") | I9: =IF(AND($D9<>"",I$2<>""),I$2&"."&$D9,"") | J9: =IF(AND($D9<>"",J$2<>""),J$2&"."&$D9,"") | K9: =IF(AND($D9<>"",K$2<>""),K$2&"."&$D9,"") | L9: =IF(AND($D9<>"",L$2<>""),L$2&"."&$D9,"") | M9: =IF(AND($D9<>"",M$2<>""),M$2&"."&$D9,"") | ... BB9: =IF(AND($D9<>"",BB$2<>""),BB$2&"."&$D9,"")
A10: 32 | E10: =IF(AND($D10<>"",E$2<>""), E$2&"."&$D10&"+"&E$2&"."&$C10,"") | F10: =IF(AND($D10<>"",F$2<>""),F$2&"."&$D10,"") | G10: =IF(AND($D10<>"",G$2<>""),G$2&"."&$D10,"") | H10: =IF(AND($D10<>"",H$2<>""),H$2&"."&$D10,"") | I10: =IF(AND($D10<>"",I$2<>""),I$2&"."&$D10,"") | J10: =IF(AND($D10<>"",J$2<>""),J$2&"."&$D10,"") | K10: =IF(AND($D10<>"",K$2<>""),K$2&"."&$D10,"") | L10: =IF(AND($D10<>"",L$2<>""),L$2&"."&$D10,"") | M10: =IF(AND($D10<>"",M$2<>""),M$2&"."&$D10,"") | ... BB10: =IF(AND($D10<>"",BB$2<>""),BB$2&"."&$D10,"")
A11: 33 | E11: =IF(AND($D11<>"",E$2<>""), E$2&"."&$D11&"+"&E$2&"."&$C11,"") | F11: =IF(AND($D11<>"",F$2<>""),F$2&"."&$D11,"") | G11: =IF(AND($D11<>"",G$2<>""),G$2&"."&$D11,"") | H11: =IF(AND($D11<>"",H$2<>""),H$2&"."&$D11,"") | I11: =IF(AND($D11<>"",I$2<>""),I$2&"."&$D11,"") | J11: =IF(AND($D11<>"",J$2<>""),J$2&"."&$D11,"") | K11: =IF(AND($D11<>"",K$2<>""),K$2&"."&$D11,"") | L11: =IF(AND($D11<>"",L$2<>""),L$2&"."&$D11,"") | M11: =IF(AND($D11<>"",M$2<>""),M$2&"."&$D11,"") | ... BB11: =IF(AND($D11<>"",BB$2<>""),BB$2&"."&$D11,"")
A12: 34 | B12: =IF(VLOOKUP($A12,'geocodes & mnemonic list'!$A$5:$D$55,2,FALSE)<>"",VLOOKUP($A12,'geocodes & mnemonic list'!$A$5:$D$55,2,FALSE),"") | D12: =IF(VLOOKUP($A12,'geocodes & mnemonic list'!$A$5:$E$104,5,FALSE)=0,"",VLOOKUP($A12,'geocodes & mnemonic list'!$A$5:$E$104,5,FALSE)) | E12: =IF(AND($D12<>"",E$2<>""), E$2&"."&$D12&"+"&E$2&"."&$C12,"") | F12: =IF(AND($D12<>"",F$2<>""),F$2&"."&$D12,"") | G12: =IF(AND($D12<>"",G$2<>""),G$2&"."&$D12,"") | H12: =IF(AND($D12<>"",H$2<>""),H$2&"."&$D12,"") | I12: =IF(AND($D12<>"",I$2<>""),I$2&"."&$D12,"") | J12: =IF(AND($D12<>"",J$2<>""),J$2&"."&$D12,"") | K12: =IF(AND($D12<>"",K$2<>""),K$2&"."&$D12,"") | L12: =IF(AND($D12<>"",L$2<>""),L$2&"."&$D12,"") | M12: =IF(AND($D12<>"",M$2<>""),M$2&"."&$D12,"") | ... BB12: =IF(AND($D12<>"",BB$2<>""),BB$2&"."&$D12,"")
A13: 35 | B13: =IF(VLOOKUP($A13,'geocodes & mnemonic list'!$A$5:$D$55,2,FALSE)<>"",VLOOKUP($A13,'geocodes & mnemonic list'!$A$5:$D$55,2,FALSE),"") | D13: =IF(VLOOKUP($A13,'geocodes & mnemonic list'!$A$5:$E$104,5,FALSE)=0,"",VLOOKUP($A13,'geocodes & mnemonic list'!$A$5:$E$104,5,FALSE)) | E13: =IF(AND($D13<>"",E$2<>""), E$2&"."&$D13&"+"&E$2&"."&$C13,"") | F13: =IF(AND($D13<>"",F$2<>""),F$2&"."&$D13,"") | G13: =IF(AND($D13<>"",G$2<>""),G$2&"."&$D13,"") | H13: =IF(AND($D13<>"",H$2<>""),H$2&"."&$D13,"") | I13: =IF(AND($D13<>"",I$2<>""),I$2&"."&$D13,"") | J13: =IF(AND($D13<>"",J$2<>""),J$2&"."&$D13,"") | K13: =IF(AND($D13<>"",K$2<>""),K$2&"."&$D13,"") | L13: =IF(AND($D13<>"",L$2<>""),L$2&"."&$D13,"") | M13: =IF(AND($D13<>"",M$2<>""),M$2&"."&$D13,"") | ... BB13: =IF(AND($D13<>"",BB$2<>""),BB$2&"."&$D13,"")
A14: 36 | B14: =IF(VLOOKUP($A14,'geocodes & mnemonic list'!$A$5:$D$55,2,FALSE)<>"",VLOOKUP($A14,'geocodes & mnemonic list'!$A$5:$D$55,2,FALSE),"") | D14: =IF(VLOOKUP($A14,'geocodes & mnemonic list'!$A$5:$E$104,5,FALSE)=0,"",VLOOKUP($A14,'geocodes & mnemonic list'!$A$5:$E$104,5,FALSE)) | E14: =IF(AND($D14<>"",E$2<>""), E$2&"."&$D14&"+"&E$2&"."&$C14,"") | F14: =IF(AND($D14<>"",F$2<>""),F$2&"."&$D14,"") | G14: =IF(AND($D14<>"",G$2<>""),G$2&"."&$D14,"") | H14: =IF(AND($D14<>"",H$2<>""),H$2&"."&$D14,"") | I14: =IF(AND($D14<>"",I$2<>""),I$2&"."&$D14,"") | J14: =IF(AND($D14<>"",J$2<>""),J$2&"."&$D14,"") | K14: =IF(AND($D14<>"",K$2<>""),K$2&"."&$D14,"") | L14: =IF(AND($D14<>"",L$2<>""),L$2&"."&$D14,"") | M14: =IF(AND($D14<>"",M$2<>""),M$2&"."&$D14,"") | ... BB14: =IF(AND($D14<>"",BB$2<>""),BB$2&"."&$D14,"")
A15: 37 | B15: =IF(VLOOKUP($A15,'geocodes & mnemonic list'!$A$5:$D$55,2,FALSE)<>"",VLOOKUP($A15,'geocodes & mnemonic list'!$A$5:$D$55,2,FALSE),"") | D15: =IF(VLOOKUP($A15,'geocodes & mnemonic list'!$A$5:$E$104,5,FALSE)=0,"",VLOOKUP($A15,'geocodes & mnemonic list'!$A$5:$E$104,5,FALSE)) | E15: =IF(AND($D15<>"",E$2<>""), E$2&"."&$D15&"+"&E$2&"."&$C15,"") | F15: =IF(AND($D15<>"",F$2<>""),F$2&"."&$D15,"") | G15: =IF(AND($D15<>"",G$2<>""),G$2&"."&$D15,"") | H15: =IF(AND($D15<>"",H$2<>""),H$2&"."&$D15,"") | I15: =IF(AND($D15<>"",I$2<>""),I$2&"."&$D15,"") | J15: =IF(AND($D15<>"",J$2<>""),J$2&"."&$D15,"") | K15: =IF(AND($D15<>"",K$2<>""),K$2&"."&$D15,"") | L15: =IF(AND($D15<>"",L$2<>""),L$2&"."&$D15,"") | M15: =IF(AND($D15<>"",M$2<>""),M$2&"."&$D15,"") | ... BB15: =IF(AND($D15<>"",BB$2<>""),BB$2&"."&$D15,"")
A16: 38 | B16: =IF(VLOOKUP($A16,'geocodes & mnemonic list'!$A$5:$D$55,2,FALSE)<>"",VLOOKUP($A16,'geocodes & mnemonic list'!$A$5:$D$55,2,FALSE),"") | D16: =IF(VLOOKUP($A16,'geocodes & mnemonic list'!$A$5:$E$104,5,FALSE)=0,"",VLOOKUP($A16,'geocodes & mnemonic list'!$A$5:$E$104,5,FALSE)) | E16: =IF(AND($D16<>"",E$2<>""), E$2&"."&$D16&"+"&E$2&"."&$C16,"") | F16: =IF(AND($D16<>"",F$2<>""),F$2&"."&$D16,"") | G16: =IF(AND($D16<>"",G$2<>""),G$2&"."&$D16,"") | H16: =IF(AND($D16<>"",H$2<>""),H$2&"."&$D16,"") | I16: =IF(AND($D16<>"",I$2<>""),I$2&"."&$D16,"") | J16: =IF(AND($D16<>"",J$2<>""),J$2&"."&$D16,"") | K16: =IF(AND($D16<>"",K$2<>""),K$2&"."&$D16,"") | L16: =IF(AND($D16<>"",L$2<>""),L$2&"."&$D16,"") | M16: =IF(AND($D16<>"",M$2<>""),M$2&"."&$D16,"") | ... BB16: =IF(AND($D16<>"",BB$2<>""),BB$2&"."&$D16,"")
A17: 39 | B17: =IF(VLOOKUP($A17,'geocodes & mnemonic list'!$A$5:$D$55,2,FALSE)<>"",VLOOKUP($A17,'geocodes & mnemonic list'!$A$5:$D$55,2,FALSE),"") | D17: =IF(VLOOKUP($A17,'geocodes & mnemonic list'!$A$5:$E$104,5,FALSE)=0,"",VLOOKUP($A17,'geocodes & mnemonic list'!$A$5:$E$104,5,FALSE)) | E17: =IF(AND($D17<>"",E$2<>""), E$2&"."&$D17&"+"&E$2&"."&$C17,"") | F17: =IF(AND($D17<>"",F$2<>""),F$2&"."&$D17,"") | G17: =IF(AND($D17<>"",G$2<>""),G$2&"."&$D17,"") | H17: =IF(AND($D17<>"",H$2<>""),H$2&"."&$D17,"") | I17: =IF(AND($D17<>"",I$2<>""),I$2&"."&$D17,"") | J17: =IF(AND($D17<>"",J$2<>""),J$2&"."&$D17,"") | K17: =IF(AND($D17<>"",K$2<>""),K$2&"."&$D17,"") | L17: =IF(AND($D17<>"",L$2<>""),L$2&"."&$D17,"") | M17: =IF(AND($D17<>"",M$2<>""),M$2&"."&$D17,"") | ... BB17: =IF(AND($D17<>"",BB$2<>""),BB$2&"."&$D17,"")
A18: 40 | B18: =IF(VLOOKUP($A18,'geocodes & mnemonic list'!$A$5:$D$55,2,FALSE)<>"",VLOOKUP($A18,'geocodes & mnemonic list'!$A$5:$D$55,2,FALSE),"") | D18: =IF(VLOOKUP($A18,'geocodes & mnemonic list'!$A$5:$E$104,5,FALSE)=0,"",VLOOKUP($A18,'geocodes & mnemonic list'!$A$5:$E$104,5,FALSE)) | E18: =IF(AND($D18<>"",E$2<>""), E$2&"."&$D18&"+"&E$2&"."&$C18,"") | F18: =IF(AND($D18<>"",F$2<>""),F$2&"."&$D18,"") | G18: =IF(AND($D18<>"",G$2<>""),G$2&"."&$D18,"") | H18: =IF(AND($D18<>"",H$2<>""),H$2&"."&$D18,"") | I18: =IF(AND($D18<>"",I$2<>""),I$2&"."&$D18,"") | J18: =IF(AND($D18<>"",J$2<>""),J$2&"."&$D18,"") | K18: =IF(AND($D18<>"",K$2<>""),K$2&"."&$D18,"") | L18: =IF(AND($D18<>"",L$2<>""),L$2&"."&$D18,"") | M18: =IF(AND($D18<>"",M$2<>""),M$2&"."&$D18,"") | ... BB18: =IF(AND($D18<>"",BB$2<>""),BB$2&"."&$D18,"")
A19: 41 | B19: =IF(VLOOKUP($A19,'geocodes & mnemonic list'!$A$5:$D$55,2,FALSE)<>"",VLOOKUP($A19,'geocodes & mnemonic list'!$A$5:$D$55,2,FALSE),"") | D19: =IF(VLOOKUP($A19,'geocodes & mnemonic list'!$A$5:$E$104,5,FALSE)=0,"",VLOOKUP($A19,'geocodes & mnemonic list'!$A$5:$E$104,5,FALSE)) | E19: =IF(AND($D19<>"",E$2<>""), E$2&"."&$D19&"+"&E$2&"."&$C19,"") | F19: =IF(AND($D19<>"",F$2<>""),F$2&"."&$D19,"") | G19: =IF(AND($D19<>"",G$2<>""),G$2&"."&$D19,"") | H19: =IF(AND($D19<>"",H$2<>""),H$2&"."&$D19,"") | I19: =IF(AND($D19<>"",I$2<>""),I$2&"."&$D19,"") | J19: =IF(AND($D19<>"",J$2<>""),J$2&"."&$D19,"") | K19: =IF(AND($D19<>"",K$2<>""),K$2&"."&$D19,"") | L19: =IF(AND($D19<>"",L$2<>""),L$2&"."&$D19,"") | M19: =IF(AND($D19<>"",M$2<>""),M$2&"."&$D19,"") | ... BB19: =IF(AND($D19<>"",BB$2<>""),BB$2&"."&$D19,"")
A20: 42 | B20: =IF(VLOOKUP($A20,'geocodes & mnemonic list'!$A$5:$D$55,2,FALSE)<>"",VLOOKUP($A20,'geocodes & mnemonic list'!$A$5:$D$55,2,FALSE),"") | D20: =IF(VLOOKUP($A20,'geocodes & mnemonic list'!$A$5:$E$104,5,FALSE)=0,"",VLOOKUP($A20,'geocodes & mnemonic list'!$A$5:$E$104,5,FALSE))
A21: 43 | B21: =IF(VLOOKUP($A21,'geocodes & mnemonic list'!$A$5:$D$55,2,FALSE)<>"",VLOOKUP($A21,'geocodes & mnemonic list'!$A$5:$D$55,2,FALSE),"") | D21: =IF(VLOOKUP($A21,'geocodes & mnemonic list'!$A$5:$E$104,5,FALSE)=0,"",VLOOKUP($A21,'geocodes & mnemonic list'!$A$5:$E$104,5,FALSE))
A22: 44 | B22: =IF(VLOOKUP($A22,'geocodes & mnemonic list'!$A$5:$D$55,2,FALSE)<>"",VLOOKUP($A22,'geocodes & mnemonic list'!$A$5:$D$55,2,FALSE),"") | D22: =IF(VLOOKUP($A22,'geocodes & mnemonic list'!$A$5:$E$104,5,FALSE)=0,"",VLOOKUP($A22,'geocodes & mnemonic list'!$A$5:$E$104,5,FALSE))
A23: 45 | B23: =IF(VLOOKUP($A23,'geocodes & mnemonic list'!$A$5:$D$55,2,FALSE)<>"",VLOOKUP($A23,'geocodes & mnemonic list'!$A$5:$D$55,2,FALSE),"") | D23: =IF(VLOOKUP($A23,'geocodes & mnemonic list'!$A$5:$E$104,5,FALSE)=0,"",VLOOKUP($A23,'geocodes & mnemonic list'!$A$5:$E$104,5,FALSE))
A24: 46 | B24: =IF(VLOOKUP($A24,'geocodes & mnemonic list'!$A$5:$D$55,2,FALSE)<>"",VLOOKUP($A24,'geocodes & mnemonic list'!$A$5:$D$55,2,FALSE),"") | D24: =IF(VLOOKUP($A24,'geocodes & mnemonic list'!$A$5:$E$104,5,FALSE)=0,"",VLOOKUP($A24,'geocodes & mnemonic list'!$A$5:$E$104,5,FALSE))
A25: 47 | B25: =IF(VLOOKUP($A25,'geocodes & mnemonic list'!$A$5:$D$55,2,FALSE)<>"",VLOOKUP($A25,'geocodes & mnemonic list'!$A$5:$D$55,2,FALSE),"") | D25: =IF(VLOOKUP($A25,'geocodes & mnemonic list'!$A$5:$E$104,5,FALSE)=0,"",VLOOKUP($A25,'geocodes & mnemonic list'!$A$5:$E$104,5,FALSE))
A26: 48 | B26: =IF(VLOOKUP($A26,'geocodes & mnemonic list'!$A$5:$D$55,2,FALSE)<>"",VLOOKUP($A26,'geocodes & mnemonic list'!$A$5:$D$55,2,FALSE),"") | D26: =IF(VLOOKUP($A26,'geocodes & mnemonic list'!$A$5:$E$104,5,FALSE)=0,"",VLOOKUP($A26,'geocodes & mnemonic list'!$A$5:$E$104,5,FALSE))
A27: 49 | B27: =IF(VLOOKUP($A27,'geocodes & mnemonic list'!$A$5:$D$55,2,FALSE)<>"",VLOOKUP($A27,'geocodes & mnemonic list'!$A$5:$D$55,2,FALSE),"") | D27: =IF(VLOOKUP($A27,'geocodes & mnemonic list'!$A$5:$E$104,5,FALSE)=0,"",VLOOKUP($A27,'geocodes & mnemonic list'!$A$5:$E$104,5,FALSE))
A28: 50 | B28: =IF(VLOOKUP($A28,'geocodes & mnemonic list'!$A$5:$D$55,2,FALSE)<>"",VLOOKUP($A28,'geocodes & mnemonic list'!$A$5:$D$55,2,FALSE),"") | D28: =IF(VLOOKUP($A28,'geocodes & mnemonic list'!$A$5:$E$104,5,FALSE)=0,"",VLOOKUP($A28,'geocodes & mnemonic list'!$A$5:$E$104,5,FALSE))

Sheet Dict
D1: Paste from 'geocodes & mnemonic list': | I1: Copy the dictionary below into tm_dict:
I2: (Note: remember to remove comma from the last key/value set)
D3: Market | E3: MMC_abbrev | F3: Market_abbrev | G3: Geocode
C4: 1 | D4: Denver | E4: DEN | F4: DE | G4: IUSA_MDEN | I4: ="'"&D4&"': "&" ['"&E4&"', "&" '"&F4&"', "&" '"&G4&"']," -> 'Denver': ['DEN', 'DE', 'IUSA_MDEN'],
C5: 2 | D5: Los Angeles | E5: LA | F5: LA | G5: IUSA_DMLOS | I5: ="'"&D5&"': "&" ['"&E5&"', "&" '"&F5&"', "&" '"&G5&"']," -> 'Los Angeles': ['LA', 'LA', 'IUSA_DMLOS'],
C6: 3 | D6: Oakland-East Bay | E6: OAK | F6: OA | G6: IUSA_DMOAK | I6: ="'"&D6&"': "&" ['"&E6&"', "&" '"&F6&"', "&" '"&G6&"']," -> 'Oakland-East Bay': ['OAK', 'OA', 'IUSA_DMOAK'],
C7: 4 | D7: Orange County | E7: OC | F7: OC | G7: IUSA_DMANA | I7: ="'"&D7&"': "&" ['"&E7&"', "&" '"&F7&"', "&" '"&G7&"']," -> 'Orange County': ['OC', 'OC', 'IUSA_DMANA'],
C8: 5 | D8: Portland | E8: POR | F8: PO | G8: IUSA_MPOT | I8: ="'"&D8&"': "&" ['"&E8&"', "&" '"&F8&"', "&" '"&G8&"']," -> 'Portland': ['POR', 'PO', 'IUSA_MPOT'],
C9: 6 | D9: San Jose | E9: SJ | F9: SJ | G9: IUSA_MSAJ | I9: ="'"&D9&"': "&" ['"&E9&"', "&" '"&F9&"', "&" '"&G9&"']," -> 'San Jose': ['SJ', 'SJ', 'IUSA_MSAJ'],
C10: 7 | D10: San Diego | E10: SD | F10: SD | G10: IUSA_MSAN | I10: ="'"&D10&"': "&" ['"&E10&"', "&" '"&F10&"', "&" '"&G10&"']," -> 'San Diego': ['SD', 'SD', 'IUSA_MSAN'],
C11: 8 | D11: Ventura County | E11: VC | F11: VN | G11: IUSA_MOXN | I11: ="'"&D11&"': "&" ['"&E11&"', "&" '"&F11&"', "&" '"&G11&"']," -> 'Ventura County': ['VC', 'VN', 'IUSA_MOXN'],
C12: 9 | D12: Fairfield County | E12: FC | F12: FC | G12: IUSA_MBSD | I12: ="'"&D12&"': "&" ['"&E12&"', "&" '"&F12&"', "&" '"&G12&"']," -> 'Fairfield County': ['FC', 'FC', 'IUSA_MBSD'],
C13: 10 | D13: Boston | E13: BOS | F13: BO | G13: IUSA_MBOS | I13: ="'"&D13&"': "&" ['"&E13&"', "&" '"&F13&"', "&" '"&G13&"']," -> 'Boston': ['BOS', 'BO', 'IUSA_MBOS'],
C14: 11 | D14: New York Metro | E14: NYM | F14: NY | G14: IUSA_DMNWY | I14: ="'"&D14&"': "&" ['"&E14&"', "&" '"&F14&"', "&" '"&G14&"']," -> 'New York Metro': ['NYM', 'NY', 'IUSA_DMNWY'],
C15: 12 | D15: Northern New Jersey | E15: NNJ | F15: NJ | G15: IUSA_DMNEK | I15: ="'"&D15&"': "&" ['"&E15&"', "&" '"&F15&"', "&" '"&G15&"']," -> 'Northern New Jersey': ['NNJ', 'NJ', 'IUSA_DMNEK'],
... C36: 33 | D36: Raleigh-Durham 2 | E36: DUR | F36: RD | G36: IUSA_MDUR | I36: ="'"&D36&"': "&" ['"&E36&"', "&" '"&F36&"', "&" '"&G36&"']," -> 'Raleigh-Durham 2': ['DUR', 'RD', 'IUSA_MDUR'],
C37: 34
C38: 35
C39: 36
C40: 37
C41: 38
C42: 39
C43: 40
C44: 41
C45: 42
C46: 43
C47: 44
C48: 45
... C53: 50
